Traceback (most recent call last):
  File "main.py", line 251, in <module>
    with open(os.getcwd() + "/others/jornais/" + str(jornal) + ".jpg", mode="r") as f:
FileNotFoundError: [Errno 2] No such file or directory: '/home/pi/Desktop/projects/bot_infogeral/bot-infodiaria-pt/others/jornais/1.jpg'

During handling of the above exception, another exception occurred:

Traceback (most recent call last):
  File "main.py", line 262, in <module>
    bot.sendPhoto(chat_id=chat_id, photo=urlfoto)
  File "/home/pi/.local/lib/python3.7/site-packages/telepot/__init__.py", line 539, in sendPhoto
    return self._api_request_with_file('sendPhoto', _rectify(p), 'photo', photo)
  File "/home/pi/.local/lib/python3.7/site-packages/telepot/__init__.py", line 496, in _api_request_with_file
    return self._api_request(method, _rectify(params), **kwargs)
  File "/home/pi/.local/lib/python3.7/site-packages/telepot/__init__.py", line 491, in _api_request
    return api.request((self._token, method, params, files), **kwargs)
  File "/home/pi/.local/lib/python3.7/site-packages/telepot/api.py", line 155, in request
    return _parse(r)
  File "/home/pi/.local/lib/python3.7/site-packages/telepot/api.py", line 150, in _parse
    raise exception.TelegramError(description, error_code, data)
telepot.exception.TelegramError: ('Bad Request: URL host is empty', 400, {'ok': False, 'error_code': 400, 'description': 'Bad Request: URL host is empty'})



